Workbook

Sheet About
A1: Site Start-Up & Essential Document Tracker (sample)
A2: FICTIONAL DATA ONLY. The study, sites, people and figures are invented for demonstration. No real trial, site or patient information.
A4: Purpose
A5: Shows how a Clinical Trial Coordinator could track essential documents, site readiness, follow-up actions and site payments for a UK study with five sites.
A7: Tabs
A8: Dashboard - summary counts, per-site view and charts, all calculated from the other tabs
A9: Settings - report date, warning windows and drop-down lists
A10: Sites - one row per site: target vs actual Site Ready date, % documents filed, Site Ready blockers
A11: Gantt - start-up phases per site on a weekly timeline: planned against actual, with status and days vs plan
A12: Documents - one row per essential document per site: status, expiry flag, filing quality check, next action and chase date
A13: Payments - milestone payments per site: budget vs invoiced, days outstanding
A14: Contact Log - record of contact with sites and whether follow-ups are done
... A27: Filing QC: Pass if filed within the filing target after receipt, otherwise Late.

Sheet Dashboard
A1: Study DEMO-001: start-up dashboard (fictional data)
A2: Report date | B2: =Settings!$B$3 -> 46304
A4: Document flags | B4: Count | D4: Follow-up actions | E4: Count
A5: Expired | B5: =COUNTIF(Documents!$J:$J,"Expired") -> 1 | D5: Chases overdue | E5: =COUNTIF(Documents!$R:$R,"Overdue") -> 3
A6: Expiring soon | B6: =COUNTIF(Documents!$J:$J,"Expiring soon") -> 2 | D6: Chases due this week | E6: =COUNTIF(Documents!$R:$R,"Due this week") -> 9
A7: Missing | B7: =COUNTIF(Documents!$J:$J,"Missing") -> 7 | D7: Chases scheduled | E7: =COUNTIF(Documents!$R:$R,"Scheduled") -> 8
A8: In progress | B8: =COUNTIF(Documents!$J:$J,"In progress") -> 10 | D8: Site follow-ups overdue | E8: =COUNTIF('Contact Log'!$J:$J,"Overdue") -> 2
A9: OK | B9: =COUNTIF(Documents!$J:$J,"OK") -> 30
A10: Total documents | B10: =COUNTA(Documents!$A:$A)-1 -> 50 | D10: Filing quality check | E10: Count
D11: Filed on time (Pass) | E11: =COUNTIF(Documents!$O:$O,"Pass") -> 29
A12: Site status | B12: Count | D12: Filed late | E12: =COUNTIF(Documents!$O:$O,"Late") -> 4
A13: Start-up | B13: =COUNTIF(Sites!$E:$E,"Start-up") -> 2 | D13: On-time filing rate | E13: =IF(E11+E12=0,0,E11/(E11+E12)) -> 0.87878788
A14: Site Ready | B14: =COUNTIF(Sites!$E:$E,"Site Ready") -> 1
A15: Recruiting | B15: =COUNTIF(Sites!$E:$E,"Recruiting") -> 1 | D15: Payments | E15: Count
A16: On hold | B16: =COUNTIF(Sites!$E:$E,"On hold") -> 1 | D16: Invoices unpaid | E16: =COUNTIFS(Payments!$E:$E,"<>",Payments!$H:$H,"",Payments!$A:$A,"P*") -> 3
D17: Unpaid beyond overdue limit | E17: =COUNTIF(Payments!$J:$J,">"&Settings!$B$8) -> 1
A18: Start-up phases (Gantt) | B18: Count
A19: Complete | B19: =COUNTIF(Gantt!$G:$G,"Complete") -> 15
A20: In progress | B20: =COUNTIF(Gantt!$G:$G,"In progress") -> 3
A21: Late | B21: =COUNTIF(Gantt!$G:$G,"Late") -> 1
A22: On hold | B22: =COUNTIF(Gantt!$G:$G,"On hold") -> 4
A23: Not started | B23: =COUNTIF(Gantt!$G:$G,"Not started") -> 2
A25: Site | B25: % documents filed | C25: Site Ready blockers | D25: Open issues | E25: Overdue chases | F25: Days vs target | G25: Budgeted (£) | H25: Invoiced (£) | I25: Paid (£) | J25: Unpaid invoices (£)
A26: =Sites!A2&" "&Sites!B2 -> S01 Northfield General Hospital | B26: =Sites!K2 -> 1 | C26: =Sites!M2 -> 0 | D26: =Sites!L2 -> 1 | E26: =Sites!N2 -> 0 | F26: =Sites!H2 -> -4 | G26: =SUMIFS(Payments!$D:$D,Payments!$B:$B,Sites!A2) -> 7500 | H26: =SUMIFS(Payments!$F:$F,Payments!$B:$B,Sites!A2) -> 7650 | I26: =SUMIFS(Payments!$F:$F,Payments!$B:$B,Sites!A2,Payments!$G:$G,"Paid") -> 5850 | J26: =H26-I26 -> 1800
A27: =Sites!A3&" "&Sites!B3 -> S02 Riverside University Hospital | B27: =Sites!K3 -> 1 | C27: =Sites!M3 -> 1 | D27: =Sites!L3 -> 1 | E27: =Sites!N3 -> 0 | F27: =Sites!H3 -> 8 | G27: =SUMIFS(Payments!$D:$D,Payments!$B:$B,Sites!A3) -> 7500 | H27: =SUMIFS(Payments!$F:$F,Payments!$B:$B,Sites!A3) -> 5700 | I27: =SUMIFS(Payments!$F:$F,Payments!$B:$B,Sites!A3,Payments!$G:$G,"Paid") -> 0 | J27: =H27-I27 -> 5700
A28: =Sites!A4&" "&Sites!B4 -> S03 Ashdown Royal Infirmary | B28: =Sites!K4 -> 0.6 | C28: =Sites!M4 -> 2 | D28: =Sites!L4 -> 2 | E28: =Sites!N4 -> 2 | F28: =Sites!H4 | G28: =SUMIFS(Payments!$D:$D,Payments!$B:$B,Sites!A4) -> 7500 | H28: =SUMIFS(Payments!$F:$F,Payments!$B:$B,Sites!A4) -> 0 | I28: =SUMIFS(Payments!$F:$F,Payments!$B:$B,Sites!A4,Payments!$G:$G,"Paid") -> 0 | J28: =H28-I28 -> 0
A29: =Sites!A5&" "&Sites!B5 -> S04 St Wilfrid's Cancer Centre | B29: =Sites!K5 -> 0.3 | C29: =Sites!M5 -> 5 | D29: =Sites!L5 -> 2 | E29: =Sites!N5 -> 1 | F29: =Sites!H5 | G29: =SUMIFS(Payments!$D:$D,Payments!$B:$B,Sites!A5) -> 7500 | H29: =SUMIFS(Payments!$F:$F,Payments!$B:$B,Sites!A5) -> 0 | I29: =SUMIFS(Payments!$F:$F,Payments!$B:$B,Sites!A5,Payments!$G:$G,"Paid") -> 0 | J29: =H29-I29 -> 0
A30: =Sites!A6&" "&Sites!B6 -> S05 Castlebrook Hospital | B30: =Sites!K6 -> 0.4 | C30: =Sites!M6 -> 4 | D30: =Sites!L6 -> 4 | E30: =Sites!N6 -> 0 | F30: =Sites!H6 | G30: =SUMIFS(Payments!$D:$D,Payments!$B:$B,Sites!A6) -> 7500 | H30: =SUMIFS(Payments!$F:$F,Payments!$B:$B,Sites!A6) -> 0 | I30: =SUMIFS(Payments!$F:$F,Payments!$B:$B,Sites!A6,Payments!$G:$G,"Paid") -> 0 | J30: =H30-I30 -> 0
A31: Total | C31: =SUM(C26:C30) -> 12 | D31: =SUM(D26:D30) -> 10 | E31: =SUM(E26:E30) -> 3 | G31: =SUM(G26:G30) -> 37500 | H31: =SUM(H26:H30) -> 13350 | I31: =SUM(I26:I30) -> 5850 | J31: =SUM(J26:J30) -> 7500

Sheet Settings
A1: Settings
A3: Report date | B3: 46304 | C3: Fixed so the sample looks the same whenever opened. For live use, replace with =TODAY().
A4: Expiry warning (days) | B4: 60 | C4: Assumption: documents expiring within this many days are flagged 'Expiring soon'.
A5: Study | B5: DEMO-001 | C5: Fictional study code.
A6: Filing target (days) | B6: 7 | C6: Assumption: a received document should be filed in the eTMF within this many days.
A7: Chase 'due soon' window (days) | B7: 7 | C7: Assumption: chase dates within this many days show as 'Due this week'.
A8: Payment overdue (days) | B8: 30 | C8: Assumption: invoices unpaid for longer than this are highlighted.
A11: Document status list | B11: Site status list | C11: Payment status list
A12: Not started | B12: Start-up | C12: Not due
A13: Requested | B13: Site Ready | C13: Invoice received
A14: Received | B14: Recruiting | C14: Approved
A15: Filed in eTMF | B15: On hold | C15: Paid

Sheet Sites
A1: Site ID | B1: Site name | C1: Principal Investigator | D1: City | E1: Site status | F1: Target Site Ready date | G1: Actual Site Ready date | H1: Days vs target | I1: Documents required | J1: Documents filed | K1: % filed | L1: Open issues (expired / expiring / missing) | M1: Site Ready blockers | N1: Overdue chases
A2: S01 | B2: Northfield General Hospital | C2: Investigator A | D2: Leeds | E2: Recruiting | F2: 46237 | G2: 46233 | H2: =IF(G2="","",G2-F2) -> -4 | I2: =COUNTIF(Documents!$B:$B,A2) -> 10 | J2: =COUNTIFS(Documents!$B:$B,A2,Documents!$E:$E,"Filed in eTMF") -> 10 | K2: =IF(I2=0,0,J2/I2) -> 1 | L2: =COUNTIFS(Documents!$B:$B,A2,Documents!$J:$J,"Expired")+COUNTIFS(Documents!$B:$B,A2,Documents!$J:$J,"Expiring soon")+COUNTIFS(Documents!$B:$B,A2,Documents!$J:$J,"Missing") -> 1 | M2: =COUNTIFS(Documents!$B:$B,A2,Documents!$D:$D,"Y",Documents!$E:$E,"<>Filed in eTMF")+COUNTIFS(Documents!$B:$B,A2,Documents!$D:$D,"Y",Documents!$J:$J,"Expired") -> 0 | N2: =COUNTIFS(Documents!$B:$B,A2,Documents!$R:$R,"Overdue") -> 0
A3: S02 | B3: Riverside University Hospital | C3: Investigator B | D3: Bristol | E3: Site Ready | F3: 46279 | G3: 46287 | H3: =IF(G3="","",G3-F3) -> 8 | I3: =COUNTIF(Documents!$B:$B,A3) -> 10 | J3: =COUNTIFS(Documents!$B:$B,A3,Documents!$E:$E,"Filed in eTMF") -> 10 | K3: =IF(I3=0,0,J3/I3) -> 1 | L3: =COUNTIFS(Documents!$B:$B,A3,Documents!$J:$J,"Expired")+COUNTIFS(Documents!$B:$B,A3,Documents!$J:$J,"Expiring soon")+COUNTIFS(Documents!$B:$B,A3,Documents!$J:$J,"Missing") -> 1 | M3: =COUNTIFS(Documents!$B:$B,A3,Documents!$D:$D,"Y",Documents!$E:$E,"<>Filed in eTMF")+COUNTIFS(Documents!$B:$B,A3,Documents!$D:$D,"Y",Documents!$J:$J,"Expired") -> 1 | N3: =COUNTIFS(Documents!$B:$B,A3,Documents!$R:$R,"Overdue") -> 0
A4: S03 | B4: Ashdown Royal Infirmary | C4: Investigator C | D4: Manchester | E4: Start-up | F4: 46321 | H4: =IF(G4="","",G4-F4) | I4: =COUNTIF(Documents!$B:$B,A4) -> 10 | J4: =COUNTIFS(Documents!$B:$B,A4,Documents!$E:$E,"Filed in eTMF") -> 6 | K4: =IF(I4=0,0,J4/I4) -> 0.6 | L4: =COUNTIFS(Documents!$B:$B,A4,Documents!$J:$J,"Expired")+COUNTIFS(Documents!$B:$B,A4,Documents!$J:$J,"Expiring soon")+COUNTIFS(Documents!$B:$B,A4,Documents!$J:$J,"Missing") -> 2 | M4: =COUNTIFS(Documents!$B:$B,A4,Documents!$D:$D,"Y",Documents!$E:$E,"<>Filed in eTMF")+COUNTIFS(Documents!$B:$B,A4,Documents!$D:$D,"Y",Documents!$J:$J,"Expired") -> 2 | N4: =COUNTIFS(Documents!$B:$B,A4,Documents!$R:$R,"Overdue") -> 2
A5: S04 | B5: St Wilfrid's Cancer Centre | C5: Investigator D | D5: London | E5: Start-up | F5: 46335 | H5: =IF(G5="","",G5-F5) | I5: =COUNTIF(Documents!$B:$B,A5) -> 10 | J5: =COUNTIFS(Documents!$B:$B,A5,Documents!$E:$E,"Filed in eTMF") -> 3 | K5: =IF(I5=0,0,J5/I5) -> 0.3 | L5: =COUNTIFS(Documents!$B:$B,A5,Documents!$J:$J,"Expired")+COUNTIFS(Documents!$B:$B,A5,Documents!$J:$J,"Expiring soon")+COUNTIFS(Documents!$B:$B,A5,Documents!$J:$J,"Missing") -> 2 | M5: =COUNTIFS(Documents!$B:$B,A5,Documents!$D:$D,"Y",Documents!$E:$E,"<>Filed in eTMF")+COUNTIFS(Documents!$B:$B,A5,Documents!$D:$D,"Y",Documents!$J:$J,"Expired") -> 5 | N5: =COUNTIFS(Documents!$B:$B,A5,Documents!$R:$R,"Overdue") -> 1
A6: S05 | B6: Castlebrook Hospital | C6: Investigator E | D6: Glasgow | E6: On hold | F6: 46307 | H6: =IF(G6="","",G6-F6) | I6: =COUNTIF(Documents!$B:$B,A6) -> 10 | J6: =COUNTIFS(Documents!$B:$B,A6,Documents!$E:$E,"Filed in eTMF") -> 4 | K6: =IF(I6=0,0,J6/I6) -> 0.4 | L6: =COUNTIFS(Documents!$B:$B,A6,Documents!$J:$J,"Expired")+COUNTIFS(Documents!$B:$B,A6,Documents!$J:$J,"Expiring soon")+COUNTIFS(Documents!$B:$B,A6,Documents!$J:$J,"Missing") -> 4 | M6: =COUNTIFS(Documents!$B:$B,A6,Documents!$D:$D,"Y",Documents!$E:$E,"<>Filed in eTMF")+COUNTIFS(Documents!$B:$B,A6,Documents!$D:$D,"Y",Documents!$J:$J,"Expired") -> 4 | N6: =COUNTIFS(Documents!$B:$B,A6,Documents!$R:$R,"Overdue") -> 0
A8: Site Ready blockers = documents marked 'Needed for Site Ready' that are not yet filed, plus any that are filed but expired.

Sheet Gantt
A1: Site start-up Gantt chart: planned phases against actual progress (fictional data)
A2: Site ID | B2: Phase | C2: Planned start | D2: Planned end | E2: Actual start | F2: Actual end | G2: Status | H2: Days vs plan | I2: Chart start | J2: Chart end | K2: 46125 | L2: =K2+7 -> 46132 | M2: =L2+7 -> 46139 | N2: =M2+7 -> 46146 | O2: =N2+7 -> 46153 | P2: =O2+7 -> 46160 | Q2: =P2+7 -> 46167 | R2: =Q2+7 -> 46174 | S2: =R2+7 -> 46181 | ... AU2: =AT2+7 -> 46377
A3: S01 | B3: Feasibility and site selection | C3: 46125 | D3: 46153 | E3: 46125 | F3: 46153 | G3: =IF(F3<>"","Complete",IF(INDEX(Sites!$E$2:$E$6,MATCH($A3,Sites!$A$2:$A$6,0))="On hold","On hold",IF(D3<Settings!$B$3,"Late",IF(E3<>"","In progress","Not started")))) -> Complete | H3: =IF(F3<>"",F3-D3,IF(G3="Late",Settings!$B$3-D3,"")) -> 0 | I3: =IF(E3<>"",E3,C3) -> 46125 | J3: =IF(F3<>"",F3,D3) -> 46153
A4: S01 | B4: Contract and budget (CTRA) | C4: 46153 | D4: 46209 | E4: 46153 | F4: 46202 | G4: =IF(F4<>"","Complete",IF(INDEX(Sites!$E$2:$E$6,MATCH($A4,Sites!$A$2:$A$6,0))="On hold","On hold",IF(D4<Settings!$B$3,"Late",IF(E4<>"","In progress","Not started")))) -> Complete | H4: =IF(F4<>"",F4-D4,IF(G4="Late",Settings!$B$3-D4,"")) -> -7 | I4: =IF(E4<>"",E4,C4) -> 46153 | J4: =IF(F4<>"",F4,D4) -> 46202
A5: S01 | B5: Ethics and regulatory approvals | C5: 46153 | D5: 46202 | E5: 46153 | F5: 46199 | G5: =IF(F5<>"","Complete",IF(INDEX(Sites!$E$2:$E$6,MATCH($A5,Sites!$A$2:$A$6,0))="On hold","On hold",IF(D5<Settings!$B$3,"Late",IF(E5<>"","In progress","Not started")))) -> Complete | H5: =IF(F5<>"",F5-D5,IF(G5="Late",Settings!$B$3-D5,"")) -> -3 | I5: =IF(E5<>"",E5,C5) -> 46153 | J5: =IF(F5<>"",F5,D5) -> 46199
A6: S01 | B6: Essential document collection | C6: 46160 | D6: 46223 | E6: 46160 | F6: 46219 | G6: =IF(F6<>"","Complete",IF(INDEX(Sites!$E$2:$E$6,MATCH($A6,Sites!$A$2:$A$6,0))="On hold","On hold",IF(D6<Settings!$B$3,"Late",IF(E6<>"","In progress","Not started")))) -> Complete | H6: =IF(F6<>"",F6-D6,IF(G6="Late",Settings!$B$3-D6,"")) -> -4 | I6: =IF(E6<>"",E6,C6) -> 46160 | J6: =IF(F6<>"",F6,D6) -> 46219
A7: S01 | B7: Site initiation visit and Site Ready | C7: =D7-14 -> 46223 | D7: =Sites!F2 -> 46237 | E7: 46223 | F7: =IF(Sites!G2="","",Sites!G2) -> 46233 | G7: =IF(F7<>"","Complete",IF(INDEX(Sites!$E$2:$E$6,MATCH($A7,Sites!$A$2:$A$6,0))="On hold","On hold",IF(D7<Settings!$B$3,"Late",IF(E7<>"","In progress","Not started")))) -> Complete | H7: =IF(F7<>"",F7-D7,IF(G7="Late",Settings!$B$3-D7,"")) -> -4 | I7: =IF(E7<>"",E7,C7) -> 46223 | J7: =IF(F7<>"",F7,D7) -> 46233
A8: S02 | B8: Feasibility and site selection | C8: 46167 | D8: 46195 | E8: 46167 | F8: 46195 | G8: =IF(F8<>"","Complete",IF(INDEX(Sites!$E$2:$E$6,MATCH($A8,Sites!$A$2:$A$6,0))="On hold","On hold",IF(D8<Settings!$B$3,"Late",IF(E8<>"","In progress","Not started")))) -> Complete | H8: =IF(F8<>"",F8-D8,IF(G8="Late",Settings!$B$3-D8,"")) -> 0 | I8: =IF(E8<>"",E8,C8) -> 46167 | J8: =IF(F8<>"",F8,D8) -> 46195
A9: S02 | B9: Contract and budget (CTRA) | C9: 46195 | D9: 46251 | E9: 46195 | F9: 46251 | G9: =IF(F9<>"","Complete",IF(INDEX(Sites!$E$2:$E$6,MATCH($A9,Sites!$A$2:$A$6,0))="On hold","On hold",IF(D9<Settings!$B$3,"Late",IF(E9<>"","In progress","Not started")))) -> Complete | H9: =IF(F9<>"",F9-D9,IF(G9="Late",Settings!$B$3-D9,"")) -> 0 | I9: =IF(E9<>"",E9,C9) -> 46195 | J9: =IF(F9<>"",F9,D9) -> 46251
A10: S02 | B10: Ethics and regulatory approvals | C10: 46195 | D10: 46244 | E10: 46195 | F10: 46248 | G10: =IF(F10<>"","Complete",IF(INDEX(Sites!$E$2:$E$6,MATCH($A10,Sites!$A$2:$A$6,0))="On hold","On hold",IF(D10<Settings!$B$3,"Late",IF(E10<>"","In progress","Not started")))) -> Complete | H10: =IF(F10<>"",F10-D10,IF(G10="Late",Settings!$B$3-D10,"")) -> 4 | I10: =IF(E10<>"",E10,C10) -> 46195 | J10: =IF(F10<>"",F10,D10) -> 46248
A11: S02 | B11: Essential document collection | C11: 46195 | D11: 46265 | E11: 46195 | F11: 46262 | G11: =IF(F11<>"","Complete",IF(INDEX(Sites!$E$2:$E$6,MATCH($A11,Sites!$A$2:$A$6,0))="On hold","On hold",IF(D11<Settings!$B$3,"Late",IF(E11<>"","In progress","Not started")))) -> Complete | H11: =IF(F11<>"",F11-D11,IF(G11="Late",Settings!$B$3-D11,"")) -> -3 | I11: =IF(E11<>"",E11,C11) -> 46195 | J11: =IF(F11<>"",F11,D11) -> 46262
A12: S02 | B12: Site initiation visit and Site Ready | C12: =D12-14 -> 46265 | D12: =Sites!F3 -> 46279 | E12: 46266 | F12: =IF(Sites!G3="","",Sites!G3) -> 46287 | G12: =IF(F12<>"","Complete",IF(INDEX(Sites!$E$2:$E$6,MATCH($A12,Sites!$A$2:$A$6,0))="On hold","On hold",IF(D12<Settings!$B$3,"Late",IF(E12<>"","In progress","Not started")))) -> Complete | H12: =IF(F12<>"",F12-D12,IF(G12="Late",Settings!$B$3-D12,"")) -> 8 | I12: =IF(E12<>"",E12,C12) -> 46266 | J12: =IF(F12<>"",F12,D12) -> 46287
A13: S03 | B13: Feasibility and site selection | C13: 46209 | D13: 46237 | E13: 46209 | F13: 46237 | G13: =IF(F13<>"","Complete",IF(INDEX(Sites!$E$2:$E$6,MATCH($A13,Sites!$A$2:$A$6,0))="On hold","On hold",IF(D13<Settings!$B$3,"Late",IF(E13<>"","In progress","Not started")))) -> Complete | H13: =IF(F13<>"",F13-D13,IF(G13="Late",Settings!$B$3-D13,"")) -> 0 | I13: =IF(E13<>"",E13,C13) -> 46209 | J13: =IF(F13<>"",F13,D13) -> 46237
A14: S03 | B14: Contract and budget (CTRA) | C14: 46237 | D14: 46293 | E14: 46237 | F14: 46284 | G14: =IF(F14<>"","Complete",IF(INDEX(Sites!$E$2:$E$6,MATCH($A14,Sites!$A$2:$A$6,0))="On hold","On hold",IF(D14<Settings!$B$3,"Late",IF(E14<>"","In progress","Not started")))) -> Complete | H14: =IF(F14<>"",F14-D14,IF(G14="Late",Settings!$B$3-D14,"")) -> -9 | I14: =IF(E14<>"",E14,C14) -> 46237 | J14: =IF(F14<>"",F14,D14) -> 46284
A15: S03 | B15: Ethics and regulatory approvals | C15: 46237 | D15: 46286 | E15: 46237 | F15: 46278 | G15: =IF(F15<>"","Complete",IF(INDEX(Sites!$E$2:$E$6,MATCH($A15,Sites!$A$2:$A$6,0))="On hold","On hold",IF(D15<Settings!$B$3,"Late",IF(E15<>"","In progress","Not started")))) -> Complete | H15: =IF(F15<>"",F15-D15,IF(G15="Late",Settings!$B$3-D15,"")) -> -8 | I15: =IF(E15<>"",E15,C15) -> 46237 | J15: =IF(F15<>"",F15,D15) -> 46278
A16: S03 | B16: Essential document collection | C16: 46244 | D16: 46307 | E16: 46244 | G16: =IF(F16<>"","Complete",IF(INDEX(Sites!$E$2:$E$6,MATCH($A16,Sites!$A$2:$A$6,0))="On hold","On hold",IF(D16<Settings!$B$3,"Late",IF(E16<>"","In progress","Not started")))) -> In progress | H16: =IF(F16<>"",F16-D16,IF(G16="Late",Settings!$B$3-D16,"")) | I16: =IF(E16<>"",E16,C16) -> 46244 | J16: =IF(F16<>"",F16,D16) -> 46307
A17: S03 | B17: Site initiation visit and Site Ready | C17: =D17-14 -> 46307 | D17: =Sites!F4 -> 46321 | F17: =IF(Sites!G4="","",Sites!G4) | G17: =IF(F17<>"","Complete",IF(INDEX(Sites!$E$2:$E$6,MATCH($A17,Sites!$A$2:$A$6,0))="On hold","On hold",IF(D17<Settings!$B$3,"Late",IF(E17<>"","In progress","Not started")))) -> Not started | H17: =IF(F17<>"",F17-D17,IF(G17="Late",Settings!$B$3-D17,"")) | I17: =IF(E17<>"",E17,C17) -> 46307 | J17: =IF(F17<>"",F17,D17) -> 46321
A18: S04 | B18: Feasibility and site selection | C18: 46223 | D18: 46251 | E18: 46223 | F18: 46251 | G18: =IF(F18<>"","Complete",IF(INDEX(Sites!$E$2:$E$6,MATCH($A18,Sites!$A$2:$A$6,0))="On hold","On hold",IF(D18<Settings!$B$3,"Late",IF(E18<>"","In progress","Not started")))) -> Complete | H18: =IF(F18<>"",F18-D18,IF(G18="Late",Settings!$B$3-D18,"")) -> 0 | I18: =IF(E18<>"",E18,C18) -> 46223 | J18: =IF(F18<>"",F18,D18) -> 46251
A19: S04 | B19: Contract and budget (CTRA) | C19: 46251 | D19: 46307 | E19: 46251 | G19: =IF(F19<>"","Complete",IF(INDEX(Sites!$E$2:$E$6,MATCH($A19,Sites!$A$2:$A$6,0))="On hold","On hold",IF(D19<Settings!$B$3,"Late",IF(E19<>"","In progress","Not started")))) -> In progress | H19: =IF(F19<>"",F19-D19,IF(G19="Late",Settings!$B$3-D19,"")) | I19: =IF(E19<>"",E19,C19) -> 46251 | J19: =IF(F19<>"",F19,D19) -> 46307
A20: S04 | B20: Ethics and regulatory approvals | C20: 46251 | D20: 46300 | E20: 46251 | G20: =IF(F20<>"","Complete",IF(INDEX(Sites!$E$2:$E$6,MATCH($A20,Sites!$A$2:$A$6,0))="On hold","On hold",IF(D20<Settings!$B$3,"Late",IF(E20<>"","In progress","Not started")))) -> Late | H20: =IF(F20<>"",F20-D20,IF(G20="Late",Settings!$B$3-D20,"")) -> 4 | I20: =IF(E20<>"",E20,C20) -> 46251 | J20: =IF(F20<>"",F20,D20) -> 46300
A21: S04 | B21: Essential document collection | C21: 46266 | D21: 46321 | E21: 46266 | G21: =IF(F21<>"","Complete",IF(INDEX(Sites!$E$2:$E$6,MATCH($A21,Sites!$A$2:$A$6,0))="On hold","On hold",IF(D21<Settings!$B$3,"Late",IF(E21<>"","In progress","Not started")))) -> In progress | H21: =IF(F21<>"",F21-D21,IF(G21="Late",Settings!$B$3-D21,"")) | I21: =IF(E21<>"",E21,C21) -> 46266 | J21: =IF(F21<>"",F21,D21) -> 46321
A22: S04 | B22: Site initiation visit and Site Ready | C22: =D22-14 -> 46321 | D22: =Sites!F5 -> 46335 | F22: =IF(Sites!G5="","",Sites!G5) | G22: =IF(F22<>"","Complete",IF(INDEX(Sites!$E$2:$E$6,MATCH($A22,Sites!$A$2:$A$6,0))="On hold","On hold",IF(D22<Settings!$B$3,"Late",IF(E22<>"","In progress","Not started")))) -> Not started | H22: =IF(F22<>"",F22-D22,IF(G22="Late",Settings!$B$3-D22,"")) | I22: =IF(E22<>"",E22,C22) -> 46321 | J22: =IF(F22<>"",F22,D22) -> 46335
A23: S05 | B23: Feasibility and site selection | C23: 46195 | D23: 46223 | E23: 46195 | F23: 46223 | G23: =IF(F23<>"","Complete",IF(INDEX(Sites!$E$2:$E$6,MATCH($A23,Sites!$A$2:$A$6,0))="On hold","On hold",IF(D23<Settings!$B$3,"Late",IF(E23<>"","In progress","Not started")))) -> Complete | H23: =IF(F23<>"",F23-D23,IF(G23="Late",Settings!$B$3-D23,"")) -> 0 | I23: =IF(E23<>"",E23,C23) -> 46195 | J23: =IF(F23<>"",F23,D23) -> 46223
A24: S05 | B24: Contract and budget (CTRA) | C24: 46223 | D24: 46279 | E24: 46223 | G24: =IF(F24<>"","Complete",IF(INDEX(Sites!$E$2:$E$6,MATCH($A24,Sites!$A$2:$A$6,0))="On hold","On hold",IF(D24<Settings!$B$3,"Late",IF(E24<>"","In progress","Not started")))) -> On hold | H24: =IF(F24<>"",F24-D24,IF(G24="Late",Settings!$B$3-D24,"")) | I24: =IF(E24<>"",E24,C24) -> 46223 | J24: =IF(F24<>"",F24,D24) -> 46279
A25: S05 | B25: Ethics and regulatory approvals | C25: 46223 | D25: 46272 | E25: 46223 | G25: =IF(F25<>"","Complete",IF(INDEX(Sites!$E$2:$E$6,MATCH($A25,Sites!$A$2:$A$6,0))="On hold","On hold",IF(D25<Settings!$B$3,"Late",IF(E25<>"","In progress","Not started")))) -> On hold | H25: =IF(F25<>"",F25-D25,IF(G25="Late",Settings!$B$3-D25,"")) | I25: =IF(E25<>"",E25,C25) -> 46223 | J25: =IF(F25<>"",F25,D25) -> 46272
A26: S05 | B26: Essential document collection | C26: 46223 | D26: 46293 | E26: 46223 | G26: =IF(F26<>"","Complete",IF(INDEX(Sites!$E$2:$E$6,MATCH($A26,Sites!$A$2:$A$6,0))="On hold","On hold",IF(D26<Settings!$B$3,"Late",IF(E26<>"","In progress","Not started")))) -> On hold | H26: =IF(F26<>"",F26-D26,IF(G26="Late",Settings!$B$3-D26,"")) | I26: =IF(E26<>"",E26,C26) -> 46223 | J26: =IF(F26<>"",F26,D26) -> 46293
A27: S05 | B27: Site initiation visit and Site Ready | C27: =D27-14 -> 46293 | D27: =Sites!F6 -> 46307 | F27: =IF(Sites!G6="","",Sites!G6) | G27: =IF(F27<>"","Complete",IF(INDEX(Sites!$E$2:$E$6,MATCH($A27,Sites!$A$2:$A$6,0))="On hold","On hold",IF(D27<Settings!$B$3,"Late",IF(E27<>"","In progress","Not started")))) -> On hold | H27: =IF(F27<>"",F27-D27,IF(G27="Late",Settings!$B$3-D27,"")) | I27: =IF(E27<>"",E27,C27) -> 46293 | J27: =IF(F27<>"",F27,D27) -> 46307
A29: Key
B30: Complete
B31: In progress
B32: Late
B33: On hold
B34: Not started
B35: Overrun past planned end (late phases)
B36: Week containing the report date
A38: Each column is one week, starting on the Monday shown. The first week (blue) is typed; the rest add 7 days.
A39: Bars are drawn by conditional formatting, not typed: a cell is coloured when its week falls between Chart start and Chart end.
A40: Chart start and Chart end use the actual dates where they exist, otherwise the planned dates.
A41: Status: Complete if there is an actual end date; On hold if the site is on hold; Late if the planned end has passed; In progress if started.
A42: Green dates on the last phase of each site are pulled from the Sites tab (target and actual Site Ready date).
...

Sheet Documents
A1: Doc ID | B1: Site ID | C1: Document type | D1: Needed for Site Ready? | E1: Status | F1: Date requested | G1: Date received | H1: Expiry date | I1: Days to expiry | J1: Flag | K1: Owner | L1: Notes | M1: Date filed in eTMF | N1: Days to file | O1: Filing QC | P1: Next action | Q1: Chase date | R1: Chase status
A2: D001 | B2: S01 | C2: Signed protocol signature page | D2: Y | E2: Filed in eTMF | F2: 46160 | G2: 46180 | I2: =IF(H2="","",H2-Settings!$B$3) | J2: =IF(E2="Not started","Missing",IF(AND(H2<>"",H2<Settings!$B$3),"Expired",IF(AND(H2<>"",H2-Settings!$B$3<=Settings!$B$4),"Expiring soon",IF(E2="Filed in eTMF","OK","In progress")))) -> OK | K2: CTC | M2: 46186 | N2: =IF(OR(M2="",G2=""),"",M2-G2) -> 6 | O2: =IF(N2="","",IF(N2<=Settings!$B$6,"Pass","Late")) -> Pass | R2: =IF(Q2="","",IF(Q2<Settings!$B$3,"Overdue",IF(Q2-Settings!$B$3<=Settings!$B$7,"Due this week","Scheduled")))
A3: D002 | B3: S01 | C3: Investigator CV (signed and dated) | D3: Y | E3: Filed in eTMF | F3: 46163 | G3: 46183 | I3: =IF(H3="","",H3-Settings!$B$3) | J3: =IF(E3="Not started","Missing",IF(AND(H3<>"",H3<Settings!$B$3),"Expired",IF(AND(H3<>"",H3-Settings!$B$3<=Settings!$B$4),"Expiring soon",IF(E3="Filed in eTMF","OK","In progress")))) -> OK | K3: CTC | M3: 46188 | N3: =IF(OR(M3="",G3=""),"",M3-G3) -> 5 | O3: =IF(N3="","",IF(N3<=Settings!$B$6,"Pass","Late")) -> Pass | R3: =IF(Q3="","",IF(Q3<Settings!$B$3,"Overdue",IF(Q3-Settings!$B$3<=Settings!$B$7,"Due this week","Scheduled")))
A4: D003 | B4: S01 | C4: PI GCP certificate | D4: Y | E4: Filed in eTMF | F4: 46166 | G4: 46188 | H4: 46346 | I4: =IF(H4="","",H4-Settings!$B$3) -> 42 | J4: =IF(E4="Not started","Missing",IF(AND(H4<>"",H4<Settings!$B$3),"Expired",IF(AND(H4<>"",H4-Settings!$B$3<=Settings!$B$4),"Expiring soon",IF(E4="Filed in eTMF","OK","In progress")))) -> Expiring soon | K4: CTC | L4: Reminder sent to PI | M4: 46190 | N4: =IF(OR(M4="",G4=""),"",M4-G4) -> 2 | O4: =IF(N4="","",IF(N4<=Settings!$B$6,"Pass","Late")) -> Pass | P4: Request renewed certificate before expiry | Q4: 46325 | R4: =IF(Q4="","",IF(Q4<Settings!$B$3,"Overdue",IF(Q4-Settings!$B$3<=Settings!$B$7,"Due this week","Scheduled"))) -> Scheduled
A5: D004 | B5: S01 | C5: REC / HRA approval letter | D5: Y | E5: Filed in eTMF | F5: 46169 | G5: 46180 | I5: =IF(H5="","",H5-Settings!$B$3) | J5: =IF(E5="Not started","Missing",IF(AND(H5<>"",H5<Settings!$B$3),"Expired",IF(AND(H5<>"",H5-Settings!$B$3<=Settings!$B$4),"Expiring soon",IF(E5="Filed in eTMF","OK","In progress")))) -> OK | K5: CTC | M5: 46186 | N5: =IF(OR(M5="",G5=""),"",M5-G5) -> 6 | O5: =IF(N5="","",IF(N5<=Settings!$B$6,"Pass","Late")) -> Pass | R5: =IF(Q5="","",IF(Q5<Settings!$B$3,"Overdue",IF(Q5-Settings!$B$3<=Settings!$B$7,"Due this week","Scheduled")))
A6: D005 | B6: S01 | C6: MHRA approval | D6: Y | E6: Filed in eTMF | F6: 46172 | G6: 46193 | I6: =IF(H6="","",H6-Settings!$B$3) | J6: =IF(E6="Not started","Missing",IF(AND(H6<>"",H6<Settings!$B$3),"Expired",IF(AND(H6<>"",H6-Settings!$B$3<=Settings!$B$4),"Expiring soon",IF(E6="Filed in eTMF","OK","In progress")))) -> OK | K6: CTC | M6: 46205 | N6: =IF(OR(M6="",G6=""),"",M6-G6) -> 12 | O6: =IF(N6="","",IF(N6<=Settings!$B$6,"Pass","Late")) -> Late | R6: =IF(Q6="","",IF(Q6<Settings!$B$3,"Overdue",IF(Q6-Settings!$B$3<=Settings!$B$7,"Due this week","Scheduled")))
A7: D006 | B7: S01 | C7: Clinical trial agreement (CTRA) fully signed | D7: Y | E7: Filed in eTMF | F7: 46175 | G7: 46186 | I7: =IF(H7="","",H7-Settings!$B$3) | J7: =IF(E7="Not started","Missing",IF(AND(H7<>"",H7<Settings!$B$3),"Expired",IF(AND(H7<>"",H7-Settings!$B$3<=Settings!$B$4),"Expiring soon",IF(E7="Filed in eTMF","OK","In progress")))) -> OK | K7: CTC | M7: 46187 | N7: =IF(OR(M7="",G7=""),"",M7-G7) -> 1 | O7: =IF(N7="","",IF(N7<=Settings!$B$6,"Pass","Late")) -> Pass | R7: =IF(Q7="","",IF(Q7<Settings!$B$3,"Overdue",IF(Q7-Settings!$B$3<=Settings!$B$7,"Due this week","Scheduled")))
A8: D007 | B8: S01 | C8: Study insurance certificate | D8: Y | E8: Filed in eTMF | F8: 46178 | G8: 46198 | H8: 46753 | I8: =IF(H8="","",H8-Settings!$B$3) -> 449 | J8: =IF(E8="Not started","Missing",IF(AND(H8<>"",H8<Settings!$B$3),"Expired",IF(AND(H8<>"",H8-Settings!$B$3<=Settings!$B$4),"Expiring soon",IF(E8="Filed in eTMF","OK","In progress")))) -> OK | K8: CTC | M8: 46199 | N8: =IF(OR(M8="",G8=""),"",M8-G8) -> 1 | O8: =IF(N8="","",IF(N8<=Settings!$B$6,"Pass","Late")) -> Pass | R8: =IF(Q8="","",IF(Q8<Settings!$B$3,"Overdue",IF(Q8-Settings!$B$3<=Settings!$B$7,"Due this week","Scheduled")))
A9: D008 | B9: S01 | C9: Delegation of duties log | D9: Y | E9: Filed in eTMF | F9: 46181 | G9: 46189 | I9: =IF(H9="","",H9-Settings!$B$3) | J9: =IF(E9="Not started","Missing",IF(AND(H9<>"",H9<Settings!$B$3),"Expired",IF(AND(H9<>"",H9-Settings!$B$3<=Settings!$B$4),"Expiring soon",IF(E9="Filed in eTMF","OK","In progress")))) -> OK | K9: CTC | M9: 46195 | N9: =IF(OR(M9="",G9=""),"",M9-G9) -> 6 | O9: =IF(N9="","",IF(N9<=Settings!$B$6,"Pass","Late")) -> Pass | R9: =IF(Q9="","",IF(Q9<Settings!$B$3,"Overdue",IF(Q9-Settings!$B$3<=Settings!$B$7,"Due this week","Scheduled")))
A10: D009 | B10: S01 | C10: Laboratory accreditation certificate | D10: N | E10: Filed in eTMF | F10: 46184 | G10: 46191 | H10: 46461 | I10: =IF(H10="","",H10-Settings!$B$3) -> 157 | J10: =IF(E10="Not started","Missing",IF(AND(H10<>"",H10<Settings!$B$3),"Expired",IF(AND(H10<>"",H10-Settings!$B$3<=Settings!$B$4),"Expiring soon",IF(E10="Filed in eTMF","OK","In progress")))) -> OK | K10: CTC | M10: 46195 | N10: =IF(OR(M10="",G10=""),"",M10-G10) -> 4 | O10: =IF(N10="","",IF(N10<=Settings!$B$6,"Pass","Late")) -> Pass | R10: =IF(Q10="","",IF(Q10<Settings!$B$3,"Overdue",IF(Q10-Settings!$B$3<=Settings!$B$7,"Due this week","Scheduled")))
A11: D010 | B11: S01 | C11: Financial disclosure form | D11: N | E11: Filed in eTMF | F11: 46187 | G11: 46207 | I11: =IF(H11="","",H11-Settings!$B$3) | J11: =IF(E11="Not started","Missing",IF(AND(H11<>"",H11<Settings!$B$3),"Expired",IF(AND(H11<>"",H11-Settings!$B$3<=Settings!$B$4),"Expiring soon",IF(E11="Filed in eTMF","OK","In progress")))) -> OK | K11: CTC | M11: 46219 | N11: =IF(OR(M11="",G11=""),"",M11-G11) -> 12 | O11: =IF(N11="","",IF(N11<=Settings!$B$6,"Pass","Late")) -> Late | R11: =IF(Q11="","",IF(Q11<Settings!$B$3,"Overdue",IF(Q11-Settings!$B$3<=Settings!$B$7,"Due this week","Scheduled")))
A12: D011 | B12: S02 | C12: Signed protocol signature page | D12: Y | E12: Filed in eTMF | F12: 46195 | G12: 46206 | I12: =IF(H12="","",H12-Settings!$B$3) | J12: =IF(E12="Not started","Missing",IF(AND(H12<>"",H12<Settings!$B$3),"Expired",IF(AND(H12<>"",H12-Settings!$B$3<=Settings!$B$4),"Expiring soon",IF(E12="Filed in eTMF","OK","In progress")))) -> OK | K12: CTC | M12: 46215 | N12: =IF(OR(M12="",G12=""),"",M12-G12) -> 9 | O12: =IF(N12="","",IF(N12<=Settings!$B$6,"Pass","Late")) -> Late | R12: =IF(Q12="","",IF(Q12<Settings!$B$3,"Overdue",IF(Q12-Settings!$B$3<=Settings!$B$7,"Due this week","Scheduled")))
A13: D012 | B13: S02 | C13: Investigator CV (signed and dated) | D13: Y | E13: Filed in eTMF | F13: 46198 | G13: 46204 | I13: =IF(H13="","",H13-Settings!$B$3) | J13: =IF(E13="Not started","Missing",IF(AND(H13<>"",H13<Settings!$B$3),"Expired",IF(AND(H13<>"",H13-Settings!$B$3<=Settings!$B$4),"Expiring soon",IF(E13="Filed in eTMF","OK","In progress")))) -> OK | K13: CTC | M13: 46210 | N13: =IF(OR(M13="",G13=""),"",M13-G13) -> 6 | O13: =IF(N13="","",IF(N13<=Settings!$B$6,"Pass","Late")) -> Pass | R13: =IF(Q13="","",IF(Q13<Settings!$B$3,"Overdue",IF(Q13-Settings!$B$3<=Settings!$B$7,"Due this week","Scheduled")))
A14: D013 | B14: S02 | C14: PI GCP certificate | D14: Y | E14: Filed in eTMF | F14: 46201 | G14: 46209 | H14: 46639 | I14: =IF(H14="","",H14-Settings!$B$3) -> 335 | J14: =IF(E14="Not started","Missing",IF(AND(H14<>"",H14<Settings!$B$3),"Expired",IF(AND(H14<>"",H14-Settings!$B$3<=Settings!$B$4),"Expiring soon",IF(E14="Filed in eTMF","OK","In progress")))) -> OK | K14: CTC | M14: 46209 | N14: =IF(OR(M14="",G14=""),"",M14-G14) -> 0 | O14: =IF(N14="","",IF(N14<=Settings!$B$6,"Pass","Late")) -> Pass | R14: =IF(Q14="","",IF(Q14<Settings!$B$3,"Overdue",IF(Q14-Settings!$B$3<=Settings!$B$7,"Due this week","Scheduled")))
A15: D014 | B15: S02 | C15: REC / HRA approval letter | D15: Y | E15: Filed in eTMF | F15: 46204 | G15: 46216 | I15: =IF(H15="","",H15-Settings!$B$3) | J15: =IF(E15="Not started","Missing",IF(AND(H15<>"",H15<Settings!$B$3),"Expired",IF(AND(H15<>"",H15-Settings!$B$3<=Settings!$B$4),"Expiring soon",IF(E15="Filed in eTMF","OK","In progress")))) -> OK | K15: CTC | M15: 46218 | N15: =IF(OR(M15="",G15=""),"",M15-G15) -> 2 | O15: =IF(N15="","",IF(N15<=Settings!$B$6,"Pass","Late")) -> Pass | R15: =IF(Q15="","",IF(Q15<Settings!$B$3,"Overdue",IF(Q15-Settings!$B$3<=Settings!$B$7,"Due this week","Scheduled")))
A16: D015 | B16: S02 | C16: MHRA approval | D16: Y | E16: Filed in eTMF | F16: 46207 | G16: 46213 | I16: =IF(H16="","",H16-Settings!$B$3) | J16: =IF(E16="Not started","Missing",IF(AND(H16<>"",H16<Settings!$B$3),"Expired",IF(AND(H16<>"",H16-Settings!$B$3<=Settings!$B$4),"Expiring soon",IF(E16="Filed in eTMF","OK","In progress")))) -> OK | K16: CTC | M16: 46218 | N16: =IF(OR(M16="",G16=""),"",M16-G16) -> 5 | O16: =IF(N16="","",IF(N16<=Settings!$B$6,"Pass","Late")) -> Pass | R16: =IF(Q16="","",IF(Q16<Settings!$B$3,"Overdue",IF(Q16-Settings!$B$3<=Settings!$B$7,"Due this week","Scheduled")))
A17: D016 | B17: S02 | C17: Clinical trial agreement (CTRA) fully signed | D17: Y | E17: Filed in eTMF | F17: 46210 | G17: 46226 | I17: =IF(H17="","",H17-Settings!$B$3) | J17: =IF(E17="Not started","Missing",IF(AND(H17<>"",H17<Settings!$B$3),"Expired",IF(AND(H17<>"",H17-Settings!$B$3<=Settings!$B$4),"Expiring soon",IF(E17="Filed in eTMF","OK","In progress")))) -> OK | K17: CTC | M17: 46231 | N17: =IF(OR(M17="",G17=""),"",M17-G17) -> 5 | O17: =IF(N17="","",IF(N17<=Settings!$B$6,"Pass","Late")) -> Pass | R17: =IF(Q17="","",IF(Q17<Settings!$B$3,"Overdue",IF(Q17-Settings!$B$3<=Settings!$B$7,"Due this week","Scheduled")))
A18: D017 | B18: S02 | C18: Study insurance certificate | D18: Y | E18: Filed in eTMF | F18: 46213 | G18: 46237 | H18: 46295 | I18: =IF(H18="","",H18-Settings!$B$3) -> -9 | J18: =IF(E18="Not started","Missing",IF(AND(H18<>"",H18<Settings!$B$3),"Expired",IF(AND(H18<>"",H18-Settings!$B$3<=Settings!$B$4),"Expiring soon",IF(E18="Filed in eTMF","OK","In progress")))) -> Expired | K18: CTC | L18: Renewal requested from site 01-Oct | M18: 46243 | N18: =IF(OR(M18="",G18=""),"",M18-G18) -> 6 | O18: =IF(N18="","",IF(N18<=Settings!$B$6,"Pass","Late")) -> Pass | P18: Obtain renewed certificate (urgent) | Q18: 46307 | R18: =IF(Q18="","",IF(Q18<Settings!$B$3,"Overdue",IF(Q18-Settings!$B$3<=Settings!$B$7,"Due this week","Scheduled"))) -> Due this week
A19: D018 | B19: S02 | C19: Delegation of duties log | D19: Y | E19: Filed in eTMF | F19: 46216 | G19: 46229 | I19: =IF(H19="","",H19-Settings!$B$3) | J19: =IF(E19="Not started","Missing",IF(AND(H19<>"",H19<Settings!$B$3),"Expired",IF(AND(H19<>"",H19-Settings!$B$3<=Settings!$B$4),"Expiring soon",IF(E19="Filed in eTMF","OK","In progress")))) -> OK | K19: CTC | M19: 46241 | N19: =IF(OR(M19="",G19=""),"",M19-G19) -> 12 | O19: =IF(N19="","",IF(N19<=Settings!$B$6,"Pass","Late")) -> Late | R19: =IF(Q19="","",IF(Q19<Settings!$B$3,"Overdue",IF(Q19-Settings!$B$3<=Settings!$B$7,"Due this week","Scheduled")))
A20: D019 | B20: S02 | C20: Laboratory accreditation certificate | D20: N | E20: Filed in eTMF | F20: 46219 | G20: 46234 | H20: 46889 | I20: =IF(H20="","",H20-Settings!$B$3) -> 585 | J20: =IF(E20="Not started","Missing",IF(AND(H20<>"",H20<Settings!$B$3),"Expired",IF(AND(H20<>"",H20-Settings!$B$3<=Settings!$B$4),"Expiring soon",IF(E20="Filed in eTMF","OK","In progress")))) -> OK | K20: CTC | M20: 46234 | N20: =IF(OR(M20="",G20=""),"",M20-G20) -> 0 | O20: =IF(N20="","",IF(N20<=Settings!$B$6,"Pass","Late")) -> Pass | R20: =IF(Q20="","",IF(Q20<Settings!$B$3,"Overdue",IF(Q20-Settings!$B$3<=Settings!$B$7,"Due this week","Scheduled")))
A21: D020 | B21: S02 | C21: Financial disclosure form | D21: N | E21: Filed in eTMF | F21: 46222 | G21: 46230 | I21: =IF(H21="","",H21-Settings!$B$3) | J21: =IF(E21="Not started","Missing",IF(AND(H21<>"",H21<Settings!$B$3),"Expired",IF(AND(H21<>"",H21-Settings!$B$3<=Settings!$B$4),"Expiring soon",IF(E21="Filed in eTMF","OK","In progress")))) -> OK | K21: CTC | M21: 46235 | N21: =IF(OR(M21="",G21=""),"",M21-G21) -> 5 | O21: =IF(N21="","",IF(N21<=Settings!$B$6,"Pass","Late")) -> Pass | R21: =IF(Q21="","",IF(Q21<Settings!$B$3,"Overdue",IF(Q21-Settings!$B$3<=Settings!$B$7,"Due this week","Scheduled")))
A22: D021 | B22: S03 | C22: Signed protocol signature page | D22: Y | E22: Filed in eTMF | F22: 46244 | G22: 46258 | I22: =IF(H22="","",H22-Settings!$B$3) | J22: =IF(E22="Not started","Missing",IF(AND(H22<>"",H22<Settings!$B$3),"Expired",IF(AND(H22<>"",H22-Settings!$B$3<=Settings!$B$4),"Expiring soon",IF(E22="Filed in eTMF","OK","In progress")))) -> OK | K22: CTC | M22: 46262 | N22: =IF(OR(M22="",G22=""),"",M22-G22) -> 4 | O22: =IF(N22="","",IF(N22<=Settings!$B$6,"Pass","Late")) -> Pass | R22: =IF(Q22="","",IF(Q22<Settings!$B$3,"Overdue",IF(Q22-Settings!$B$3<=Settings!$B$7,"Due this week","Scheduled")))
A23: D022 | B23: S03 | C23: Investigator CV (signed and dated) | D23: Y | E23: Filed in eTMF | F23: 46247 | G23: 46270 | I23: =IF(H23="","",H23-Settings!$B$3) | J23: =IF(E23="Not started","Missing",IF(AND(H23<>"",H23<Settings!$B$3),"Expired",IF(AND(H23<>"",H23-Settings!$B$3<=Settings!$B$4),"Expiring soon",IF(E23="Filed in eTMF","OK","In progress")))) -> OK | K23: CTC | M23: 46271 | N23: =IF(OR(M23="",G23=""),"",M23-G23) -> 1 | O23: =IF(N23="","",IF(N23<=Settings!$B$6,"Pass","Late")) -> Pass | R23: =IF(Q23="","",IF(Q23<Settings!$B$3,"Overdue",IF(Q23-Settings!$B$3<=Settings!$B$7,"Due this week","Scheduled")))
A24: D023 | B24: S03 | C24: PI GCP certificate | D24: Y | E24: Filed in eTMF | F24: 46250 | G24: 46264 | H24: 46323 | I24: =IF(H24="","",H24-Settings!$B$3) -> 19 | J24: =IF(E24="Not started","Missing",IF(AND(H24<>"",H24<Settings!$B$3),"Expired",IF(AND(H24<>"",H24-Settings!$B$3<=Settings!$B$4),"Expiring soon",IF(E24="Filed in eTMF","OK","In progress")))) -> Expiring soon | K24: CTC | L24: PI booked on refresher course | M24: 46266 | N24: =IF(OR(M24="",G24=""),"",M24-G24) -> 2 | O24: =IF(N24="","",IF(N24<=Settings!$B$6,"Pass","Late")) -> Pass | P24: Request renewed certificate before expiry | Q24: 46302 | R24: =IF(Q24="","",IF(Q24<Settings!$B$3,"Overdue",IF(Q24-Settings!$B$3<=Settings!$B$7,"Due this week","Scheduled"))) -> Overdue
A25: D024 | B25: S03 | C25: REC / HRA approval letter | D25: Y | E25: Filed in eTMF | F25: 46253 | G25: 46275 | I25: =IF(H25="","",H25-Settings!$B$3) | J25: =IF(E25="Not started","Missing",IF(AND(H25<>"",H25<Settings!$B$3),"Expired",IF(AND(H25<>"",H25-Settings!$B$3<=Settings!$B$4),"Expiring soon",IF(E25="Filed in eTMF","OK","In progress")))) -> OK | K25: CTC | M25: 46278 | N25: =IF(OR(M25="",G25=""),"",M25-G25) -> 3 | O25: =IF(N25="","",IF(N25<=Settings!$B$6,"Pass","Late")) -> Pass | R25: =IF(Q25="","",IF(Q25<Settings!$B$3,"Overdue",IF(Q25-Settings!$B$3<=Settings!$B$7,"Due this week","Scheduled")))
A26: D025 | B26: S03 | C26: MHRA approval | D26: Y | E26: Filed in eTMF | F26: 46256 | G26: 46262 | I26: =IF(H26="","",H26-Settings!$B$3) | J26: =IF(E26="Not started","Missing",IF(AND(H26<>"",H26<Settings!$B$3),"Expired",IF(AND(H26<>"",H26-Settings!$B$3<=Settings!$B$4),"Expiring soon",IF(E26="Filed in eTMF","OK","In progress")))) -> OK | K26: CTC | M26: 46263 | N26: =IF(OR(M26="",G26=""),"",M26-G26) -> 1 | O26: =IF(N26="","",IF(N26<=Settings!$B$6,"Pass","Late")) -> Pass | R26: =IF(Q26="","",IF(Q26<Settings!$B$3,"Overdue",IF(Q26-Settings!$B$3<=Settings!$B$7,"Due this week","Scheduled")))
A27: D026 | B27: S03 | C27: Clinical trial agreement (CTRA) fully signed | D27: Y | E27: Filed in eTMF | F27: 46259 | G27: 46283 | I27: =IF(H27="","",H27-Settings!$B$3) | J27: =IF(E27="Not started","Missing",IF(AND(H27<>"",H27<Settings!$B$3),"Expired",IF(AND(H27<>"",H27-Settings!$B$3<=Settings!$B$4),"Expiring soon",IF(E27="Filed in eTMF","OK","In progress")))) -> OK | K27: CTC | M27: 46284 | N27: =IF(OR(M27="",G27=""),"",M27-G27) -> 1 | O27: =IF(N27="","",IF(N27<=Settings!$B$6,"Pass","Late")) -> Pass | R27: =IF(Q27="","",IF(Q27<Settings!$B$3,"Overdue",IF(Q27-Settings!$B$3<=Settings!$B$7,"Due this week","Scheduled")))
A28: D027 | B28: S03 | C28: Study insurance certificate | D28: Y | E28: Received | F28: 46262 | G28: 46280 | H28: 46735 | I28: =IF(H28="","",H28-Settings!$B$3) -> 431 | J28: =IF(E28="Not started","Missing",IF(AND(H28<>"",H28<Settings!$B$3),"Expired",IF(AND(H28<>"",H28-Settings!$B$3<=Settings!$B$4),"Expiring soon",IF(E28="Filed in eTMF","OK","In progress")))) -> In progress | K28: CTC | N28: =IF(OR(M28="",G28=""),"",M28-G28) | O28: =IF(N28="","",IF(N28<=Settings!$B$6,"Pass","Late")) | P28: Quality check and file in eTMF | Q28: 46306 | R28: =IF(Q28="","",IF(Q28<Settings!$B$3,"Overdue",IF(Q28-Settings!$B$3<=Settings!$B$7,"Due this week","Scheduled"))) -> Due this week
A29: D028 | B29: S03 | C29: Delegation of duties log | D29: Y | E29: Received | F29: 46265 | G29: 46283 | I29: =IF(H29="","",H29-Settings!$B$3) | J29: =IF(E29="Not started","Missing",IF(AND(H29<>"",H29<Settings!$B$3),"Expired",IF(AND(H29<>"",H29-Settings!$B$3<=Settings!$B$4),"Expiring soon",IF(E29="Filed in eTMF","OK","In progress")))) -> In progress | K29: CTC | N29: =IF(OR(M29="",G29=""),"",M29-G29) | O29: =IF(N29="","",IF(N29<=Settings!$B$6,"Pass","Late")) | P29: Quality check and file in eTMF | Q29: 46304 | R29: =IF(Q29="","",IF(Q29<Settings!$B$3,"Overdue",IF(Q29-Settings!$B$3<=Settings!$B$7,"Due this week","Scheduled"))) -> Due this week
A30: D029 | B30: S03 | C30: Laboratory accreditation certificate | D30: N | E30: Requested | F30: 46268 | I30: =IF(H30="","",H30-Settings!$B$3) | J30: =IF(E30="Not started","Missing",IF(AND(H30<>"",H30<Settings!$B$3),"Expired",IF(AND(H30<>"",H30-Settings!$B$3<=Settings!$B$4),"Expiring soon",IF(E30="Filed in eTMF","OK","In progress")))) -> In progress | K30: CTC | N30: =IF(OR(M30="",G30=""),"",M30-G30) | O30: =IF(N30="","",IF(N30<=Settings!$B$6,"Pass","Late")) | P30: Chase site for outstanding document | Q30: 46298 | R30: =IF(Q30="","",IF(Q30<Settings!$B$3,"Overdue",IF(Q30-Settings!$B$3<=Settings!$B$7,"Due this week","Scheduled"))) -> Overdue
A31: D030 | B31: S03 | C31: Financial disclosure form | D31: N | E31: Not started | I31: =IF(H31="","",H31-Settings!$B$3) | J31: =IF(E31="Not started","Missing",IF(AND(H31<>"",H31<Settings!$B$3),"Expired",IF(AND(H31<>"",H31-Settings!$B$3<=Settings!$B$4),"Expiring soon",IF(E31="Filed in eTMF","OK","In progress")))) -> Missing | K31: CTC | N31: =IF(OR(M31="",G31=""),"",M31-G31) | O31: =IF(N31="","",IF(N31<=Settings!$B$6,"Pass","Late")) | P31: Send document request to site | Q31: 46307 | R31: =IF(Q31="","",IF(Q31<Settings!$B$3,"Overdue",IF(Q31-Settings!$B$3<=Settings!$B$7,"Due this week","Scheduled"))) -> Due this week
A32: D031 | B32: S04 | C32: Signed protocol signature page | D32: Y | E32: Filed in eTMF | F32: 46266 | G32: 46272 | I32: =IF(H32="","",H32-Settings!$B$3) | J32: =IF(E32="Not started","Missing",IF(AND(H32<>"",H32<Settings!$B$3),"Expired",IF(AND(H32<>"",H32-Settings!$B$3<=Settings!$B$4),"Expiring soon",IF(E32="Filed in eTMF","OK","In progress")))) -> OK | K32: CTC | M32: 46274 | N32: =IF(OR(M32="",G32=""),"",M32-G32) -> 2 | O32: =IF(N32="","",IF(N32<=Settings!$B$6,"Pass","Late")) -> Pass | R32: =IF(Q32="","",IF(Q32<Settings!$B$3,"Overdue",IF(Q32-Settings!$B$3<=Settings!$B$7,"Due this week","Scheduled")))
A33: D032 | B33: S04 | C33: Investigator CV (signed and dated) | D33: Y | E33: Filed in eTMF | F33: 46269 | G33: 46281 | I33: =IF(H33="","",H33-Settings!$B$3) | J33: =IF(E33="Not started","Missing",IF(AND(H33<>"",H33<Settings!$B$3),"Expired",IF(AND(H33<>"",H33-Settings!$B$3<=Settings!$B$4),"Expiring soon",IF(E33="Filed in eTMF","OK","In progress")))) -> OK | K33: CTC | M33: 46281 | N33: =IF(OR(M33="",G33=""),"",M33-G33) -> 0 | O33: =IF(N33="","",IF(N33<=Settings!$B$6,"Pass","Late")) -> Pass | R33: =IF(Q33="","",IF(Q33<Settings!$B$3,"Overdue",IF(Q33-Settings!$B$3<=Settings!$B$7,"Due this week","Scheduled")))
A34: D033 | B34: S04 | C34: PI GCP certificate | D34: Y | E34: Filed in eTMF | F34: 46272 | G34: 46293 | H34: 46885 | I34: =IF(H34="","",H34-Settings!$B$3) -> 581 | J34: =IF(E34="Not started","Missing",IF(AND(H34<>"",H34<Settings!$B$3),"Expired",IF(AND(H34<>"",H34-Settings!$B$3<=Settings!$B$4),"Expiring soon",IF(E34="Filed in eTMF","OK","In progress")))) -> OK | K34: CTC | M34: 46297 | N34: =IF(OR(M34="",G34=""),"",M34-G34) -> 4 | O34: =IF(N34="","",IF(N34<=Settings!$B$6,"Pass","Late")) -> Pass | R34: =IF(Q34="","",IF(Q34<Settings!$B$3,"Overdue",IF(Q34-Settings!$B$3<=Settings!$B$7,"Due this week","Scheduled")))
A35: D034 | B35: S04 | C35: REC / HRA approval letter | D35: Y | E35: Received | F35: 46275 | G35: 46294 | I35: =IF(H35="","",H35-Settings!$B$3) | J35: =IF(E35="Not started","Missing",IF(AND(H35<>"",H35<Settings!$B$3),"Expired",IF(AND(H35<>"",H35-Settings!$B$3<=Settings!$B$4),"Expiring soon",IF(E35="Filed in eTMF","OK","In progress")))) -> In progress | K35: CTC | N35: =IF(OR(M35="",G35=""),"",M35-G35) | O35: =IF(N35="","",IF(N35<=Settings!$B$6,"Pass","Late")) | P35: Quality check and file in eTMF | Q35: 46304 | R35: =IF(Q35="","",IF(Q35<Settings!$B$3,"Overdue",IF(Q35-Settings!$B$3<=Settings!$B$7,"Due this week","Scheduled"))) -> Due this week
A36: D035 | B36: S04 | C36: MHRA approval | D36: Y | E36: Received | F36: 46278 | G36: 46302 | I36: =IF(H36="","",H36-Settings!$B$3) | J36: =IF(E36="Not started","Missing",IF(AND(H36<>"",H36<Settings!$B$3),"Expired",IF(AND(H36<>"",H36-Settings!$B$3<=Settings!$B$4),"Expiring soon",IF(E36="Filed in eTMF","OK","In progress")))) -> In progress | K36: CTC | N36: =IF(OR(M36="",G36=""),"",M36-G36) | O36: =IF(N36="","",IF(N36<=Settings!$B$6,"Pass","Late")) | P36: Quality check and file in eTMF | Q36: 46305 | R36: =IF(Q36="","",IF(Q36<Settings!$B$3,"Overdue",IF(Q36-Settings!$B$3<=Settings!$B$7,"Due this week","Scheduled"))) -> Due this week
A37: D036 | B37: S04 | C37: Clinical trial agreement (CTRA) fully signed | D37: Y | E37: Requested | F37: 46281 | I37: =IF(H37="","",H37-Settings!$B$3) | J37: =IF(E37="Not started","Missing",IF(AND(H37<>"",H37<Settings!$B$3),"Expired",IF(AND(H37<>"",H37-Settings!$B$3<=Settings!$B$4),"Expiring soon",IF(E37="Filed in eTMF","OK","In progress")))) -> In progress | K37: CTC | L37: With site R&D office for signature | N37: =IF(OR(M37="",G37=""),"",M37-G37) | O37: =IF(N37="","",IF(N37<=Settings!$B$6,"Pass","Late")) | P37: Chase site for outstanding document | Q37: 46302 | R37: =IF(Q37="","",IF(Q37<Settings!$B$3,"Overdue",IF(Q37-Settings!$B$3<=Settings!$B$7,"Due this week","Scheduled"))) -> Overdue
A38: D037 | B38: S04 | C38: Study insurance certificate | D38: Y | E38: Requested | F38: 46284 | I38: =IF(H38="","",H38-Settings!$B$3) | J38: =IF(E38="Not started","Missing",IF(AND(H38<>"",H38<Settings!$B$3),"Expired",IF(AND(H38<>"",H38-Settings!$B$3<=Settings!$B$4),"Expiring soon",IF(E38="Filed in eTMF","OK","In progress")))) -> In progress | K38: CTC | N38: =IF(OR(M38="",G38=""),"",M38-G38) | O38: =IF(N38="","",IF(N38<=Settings!$B$6,"Pass","Late")) | P38: Chase site for outstanding document | Q38: 46307 | R38: =IF(Q38="","",IF(Q38<Settings!$B$3,"Overdue",IF(Q38-Settings!$B$3<=Settings!$B$7,"Due this week","Scheduled"))) -> Due this week
A39: D038 | B39: S04 | C39: Delegation of duties log | D39: Y | E39: Requested | F39: 46287 | I39: =IF(H39="","",H39-Settings!$B$3) | J39: =IF(E39="Not started","Missing",IF(AND(H39<>"",H39<Settings!$B$3),"Expired",IF(AND(H39<>"",H39-Settings!$B$3<=Settings!$B$4),"Expiring soon",IF(E39="Filed in eTMF","OK","In progress")))) -> In progress | K39: CTC | N39: =IF(OR(M39="",G39=""),"",M39-G39) | O39: =IF(N39="","",IF(N39<=Settings!$B$6,"Pass","Late")) | P39: Chase site for outstanding document | Q39: 46309 | R39: =IF(Q39="","",IF(Q39<Settings!$B$3,"Overdue",IF(Q39-Settings!$B$3<=Settings!$B$7,"Due this week","Scheduled"))) -> Due this week
A40: D039 | B40: S04 | C40: Laboratory accreditation certificate | D40: N | E40: Not started | I40: =IF(H40="","",H40-Settings!$B$3) | J40: =IF(E40="Not started","Missing",IF(AND(H40<>"",H40<Settings!$B$3),"Expired",IF(AND(H40<>"",H40-Settings!$B$3<=Settings!$B$4),"Expiring soon",IF(E40="Filed in eTMF","OK","In progress")))) -> Missing | K40: CTC | N40: =IF(OR(M40="",G40=""),"",M40-G40) | O40: =IF(N40="","",IF(N40<=Settings!$B$6,"Pass","Late")) | P40: Send document request to site | Q40: 46311 | R40: =IF(Q40="","",IF(Q40<Settings!$B$3,"Overdue",IF(Q40-Settings!$B$3<=Settings!$B$7,"Due this week","Scheduled"))) -> Due this week
...

Sheet Payments
A1: Payment ID | B1: Site ID | C1: Milestone | D1: Budgeted (£) | E1: Invoice received | F1: Invoiced (£) | G1: Status | H1: Date paid | I1: Variance (£) | J1: Days outstanding
A2: P001 | B2: S01 | C2: Site set-up fee | D2: 4500 | E2: 46239 | F2: 4500 | G2: Paid | H2: 46262 | I2: =IF(F2="","",F2-D2) -> 0 | J2: =IF(AND(E2<>"",H2=""),Settings!$B$3-E2,"")
A3: P002 | B3: S01 | C3: First patient enrolled | D3: 1800 | E3: 46283 | F3: 1800 | G3: Approved | I3: =IF(F3="","",F3-D3) -> 0 | J3: =IF(AND(E3<>"",H3=""),Settings!$B$3-E3,"") -> 21
A4: P003 | B4: S01 | C4: Pharmacy set-up fee | D4: 1200 | E4: 46246 | F4: 1350 | G4: Paid | H4: 46269 | I4: =IF(F4="","",F4-D4) -> 150 | J4: =IF(AND(E4<>"",H4=""),Settings!$B$3-E4,"")
A5: P004 | B5: S02 | C5: Site set-up fee | D5: 4500 | E5: 46290 | F5: 4500 | G5: Invoice received | I5: =IF(F5="","",F5-D5) -> 0 | J5: =IF(AND(E5<>"",H5=""),Settings!$B$3-E5,"") -> 14
A6: P005 | B6: S02 | C6: First patient enrolled | D6: 1800 | G6: Not due | I6: =IF(F6="","",F6-D6) | J6: =IF(AND(E6<>"",H6=""),Settings!$B$3-E6,"")
A7: P006 | B7: S02 | C7: Pharmacy set-up fee | D7: 1200 | E7: 46254 | F7: 1200 | G7: Invoice received | I7: =IF(F7="","",F7-D7) -> 0 | J7: =IF(AND(E7<>"",H7=""),Settings!$B$3-E7,"") -> 50
A8: P007 | B8: S03 | C8: Site set-up fee | D8: 4500 | G8: Not due | I8: =IF(F8="","",F8-D8) | J8: =IF(AND(E8<>"",H8=""),Settings!$B$3-E8,"")
A9: P008 | B9: S03 | C9: First patient enrolled | D9: 1800 | G9: Not due | I9: =IF(F9="","",F9-D9) | J9: =IF(AND(E9<>"",H9=""),Settings!$B$3-E9,"")
A10: P009 | B10: S03 | C10: Pharmacy set-up fee | D10: 1200 | G10: Not due | I10: =IF(F10="","",F10-D10) | J10: =IF(AND(E10<>"",H10=""),Settings!$B$3-E10,"")
A11: P010 | B11: S04 | C11: Site set-up fee | D11: 4500 | G11: Not due | I11: =IF(F11="","",F11-D11) | J11: =IF(AND(E11<>"",H11=""),Settings!$B$3-E11,"")
A12: P011 | B12: S04 | C12: First patient enrolled | D12: 1800 | G12: Not due | I12: =IF(F12="","",F12-D12) | J12: =IF(AND(E12<>"",H12=""),Settings!$B$3-E12,"")
A13: P012 | B13: S04 | C13: Pharmacy set-up fee | D13: 1200 | G13: Not due | I13: =IF(F13="","",F13-D13) | J13: =IF(AND(E13<>"",H13=""),Settings!$B$3-E13,"")
A14: P013 | B14: S05 | C14: Site set-up fee | D14: 4500 | G14: Not due | I14: =IF(F14="","",F14-D14) | J14: =IF(AND(E14<>"",H14=""),Settings!$B$3-E14,"")
A15: P014 | B15: S05 | C15: First patient enrolled | D15: 1800 | G15: Not due | I15: =IF(F15="","",F15-D15) | J15: =IF(AND(E15<>"",H15=""),Settings!$B$3-E15,"")
A16: P015 | B16: S05 | C16: Pharmacy set-up fee | D16: 1200 | G16: Not due | I16: =IF(F16="","",F16-D16) | J16: =IF(AND(E16<>"",H16=""),Settings!$B$3-E16,"")
A18: Invoices unpaid for longer than the 'Payment overdue' setting are highlighted. Positive variance = invoiced above budget.

Sheet Contact Log
A1: Contact ID | B1: Date | C1: Site ID | D1: Contact (role) | E1: Method | F1: Subject | G1: Outcome | H1: Follow-up due | I1: Follow-up done? (Y/N) | J1: Follow-up status
A2: C001 | B2: 46286 | C2: S02 | D2: Research nurse | E2: Email | F2: Insurance certificate expiring 30-Sep | G2: Site to request renewal from their R&D office | H2: 46293 | I2: Y | J2: =IF(H2="","",IF(I2="Y","Done",IF(H2<Settings!$B$3,"Overdue","Open"))) -> Done
A3: C002 | B3: 46296 | C3: S02 | D3: R&D office | E3: Phone | F3: Insurance renewal not yet received | G3: Renewal in progress; certificate promised by 12-Oct | H3: 46307 | I3: N | J3: =IF(H3="","",IF(I3="Y","Done",IF(H3<Settings!$B$3,"Overdue","Open"))) -> Open
A4: C003 | B4: 46289 | C4: S03 | D4: Principal Investigator | E4: Email | F4: GCP certificate expires 28-Oct | G4: PI booked on refresher course | H4: 46302 | I4: N | J4: =IF(H4="","",IF(I4="Y","Done",IF(H4<Settings!$B$3,"Overdue","Open"))) -> Overdue
A5: C004 | B5: 46294 | C5: S04 | D5: R&D office | E5: Email | F5: CTRA signature status | G5: Contract with site legal team; update expected in one week | H5: 46301 | I5: N | J5: =IF(H5="","",IF(I5="Y","Done",IF(H5<Settings!$B$3,"Overdue","Open"))) -> Overdue
A6: C005 | B6: 46297 | C6: S04 | D6: Site coordinator | E6: Phone | F6: Outstanding start-up documents | G6: Site to send insurance certificate and delegation log | H6: 46309 | I6: N | J6: =IF(H6="","",IF(I6="Y","Done",IF(H6<Settings!$B$3,"Overdue","Open"))) -> Open
A7: C006 | B7: 46280 | C7: S05 | D7: Principal Investigator | E7: Meeting | F7: Site capacity and hold decision | G7: Site placed on hold; review in November | H7: 46328 | I7: N | J7: =IF(H7="","",IF(I7="Y","Done",IF(H7<Settings!$B$3,"Overdue","Open"))) -> Open
A8: C007 | B8: 46275 | C8: S01 | D8: Pharmacy lead | E8: Email | F8: Pharmacy set-up invoice above budget | G8: Extra dispensing visit confirmed; variance approved by CRM | H8: 46282 | I8: Y | J8: =IF(H8="","",IF(I8="Y","Done",IF(H8<Settings!$B$3,"Overdue","Open"))) -> Done
A9: C008 | B9: 46300 | C9: S02 | D9: Finance contact | E9: Email | F9: Pharmacy invoice unpaid since 20-Aug | G9: Escalated to finance for payment run | H9: 46304 | I9: N | J9: =IF(H9="","",IF(I9="Y","Done",IF(H9<Settings!$B$3,"Overdue","Open"))) -> Open
A10: C009 | B10: 46301 | C10: S01 | D10: Principal Investigator | E10: Email | F10: GCP certificate expires 20-Nov | G10: Reminder sent; PI acknowledged | H10: 46325 | I10: N | J10: =IF(H10="","",IF(I10="Y","Done",IF(H10<Settings!$B$3,"Overdue","Open"))) -> Open
A11: C010 | B11: 46302 | C11: S03 | D11: Site coordinator | E11: Phone | F11: Documents received awaiting filing | G11: Confirmed final versions; ready for QC | H11: 46305 | I11: N | J11: =IF(H11="","",IF(I11="Y","Done",IF(H11<Settings!$B$3,"Overdue","Open"))) -> Open

Sheet Change Log
A1: Change ID | B1: Date | C1: Tab | D1: Record ID | E1: Field | F1: Old value | G1: New value | H1: Changed by | I1: Reason
A2: L001 | B2: 46233 | C2: Sites | D2: S01 | E2: Actual Site Ready date | F2: (blank) | G2: 30-Jul-2026 | H2: CTC | I2: Site initiation completed; confirmed by CRA
A3: L002 | B3: 46269 | C3: Payments | D3: P003 | E3: Status | F3: Approved | G3: Paid | H3: CTC | I3: Payment confirmed by finance; variance of £150 approved by CRM
A4: L003 | B4: 46280 | C4: Sites | D4: S05 | E4: Site status | F4: Start-up | G4: On hold | H4: CTC | I4: Site capacity review; decision recorded in Contact Log C006
A5: L004 | B5: 46287 | C5: Sites | D5: S02 | E5: Actual Site Ready date | F5: (blank) | G5: 22-Sep-2026 | H5: CTC | I5: Site Ready confirmed 8 days after target; pharmacy set-up delayed
A6: L005 | B6: 46287 | C6: Sites | D6: S02 | E6: Site status | F6: Start-up | G6: Site Ready | H6: CTC | I6: All documents needed for Site Ready filed
A7: L006 | B7: 46290 | C7: Settings | D7: - | E7: Expiry warning (days) | F7: 30 | G7: 60 | H7: CTC | I7: Agreed with COM: 30 days too short to obtain renewals
A8: L007 | B8: 46296 | C8: Documents | D8: D017 | E8: Notes | F8: (blank) | G8: Renewal requested from site 01-Oct | H8: CTC | I8: Insurance expired 30-Sep; renewal chased
A9: L008 | B9: 46302 | C9: Documents | D9: D027 | E9: Status | F9: Requested | G9: Received | H9: CTC | I9: Document received from site by email
A11: Rule: never overwrite a status, date or amount without adding a row here. Entries are added, never deleted.
